#VRML_SIM R2023a utf8

EXTERNPROTO "https://raw.githubusercontent.com/cyberbotics/webots/R2023a/projects/robots/gctronic/e-puck/protos/E-puck.proto"
EXTERNPROTO "https://raw.githubusercontent.com/cyberbotics/webots/R2023a/projects/objects/backgrounds/protos/TexturedBackground.proto"
EXTERNPROTO "https://raw.githubusercontent.com/cyberbotics/webots/R2023a/projects/objects/backgrounds/protos/TexturedBackgroundLight.proto"
EXTERNPROTO "https://raw.githubusercontent.com/cyberbotics/webots/R2023a/projects/objects/floors/protos/RectangleArena.proto"
EXTERNPROTO "https://raw.githubusercontent.com/cyberbotics/webots/R2023a/projects/objects/factory/containers/protos/WoodenBox.proto"
EXTERNPROTO "https://raw.githubusercontent.com/cyberbotics/webots/R2023a/projects/appearances/protos/BrushedAluminium.proto"

WorldInfo {
  coordinateSystem "NUE"
}
Viewpoint {
  orientation -0.7082953278779357 0.705841662657821 0.0102603977861604 2.6841977335573493
  position 0.23285737952508256 2.4825289185708255 0.6514770804036776
}
TexturedBackground {
  texture "factory"
}
TexturedBackgroundLight {
}
DEF area RectangleArena {
  translation -0.257628 -4.44089e-16 -0.192172
  rotation -0.5773502691896258 0.5773502691896258 0.5773502691896258 2.0943951023931953
  floorSize 2 2
  floorTileSize 0.508 0.508
  wallHeight 0.5
  wallAppearance BrushedAluminium {
    colorOverride 0.752941 0.74902 0.737255
  }
}
WoodenBox {
  translation -0.39216973507162983 0.09980383030004439 0.5420719957683291
  rotation 1.3513374698206445e-13 -1 -1.4892790087246634e-14 0.0026049615518022404
  name "wooden box(2)"
  size 0.2 0.2 0.2
  mass 0.5
}
WoodenBox {
  translation -0.5496511214402234 0.0998038303000447 -0.38430324989754444
  rotation 1.491937375661432e-13 -1 1.7308426714242338e-14 0.002627478570300935
  name "wooden box(3)"
  size 0.2 0.2 0.2
  mass 0.5
}
WoodenBox {
  translation 0.1375152771262054 0.09980383030004483 -0.788401206151961
  rotation 3.3760020593198683e-14 -1 -2.517344464490611e-15 0.008625527724317817
  name "wooden box(1)"
  size 0.2 0.2 0.2
  mass 0.5
}
DEF epuck E-puck {
  hidden position_0_0 -7.10911615691113e-08
  hidden position_0_1 2.495457730068617e-07
  hidden linearVelocity_0 -2.6604290687921746e-10 -5.189188338287447e-12 -3.5587184160172184e-11
  hidden angularVelocity_0 -5.109402386393901e-10 1.6922044711753482e-08 7.377654861404186e-10
  hidden rotation_1 0 -1 0 7.300048299977715e-08
  hidden linearVelocity_1 3.029688870936053e-11 -2.1771207074370683e-11 8.626122082830606e-10
  hidden angularVelocity_1 5.164089139967017e-08 1.687744867698171e-08 -7.235870165277133e-09
  hidden rotation_2 0 1 0 2.493441183966625e-07
  hidden linearVelocity_2 -2.1544332383518404e-10 1.1642775786535795e-11 -7.44097234560824e-10
  hidden angularVelocity_2 -5.025803739144066e-08 1.698302315931348e-08 8.35046199540763e-09
  hidden linearVelocity_45 -2.3743005043465327e-09 -1.2566152953752407e-08 -1.9006242383320243e-10
  hidden angularVelocity_45 -3.803876075583416e-08 1.7331110694901608e-08 -2.446163413576673e-07
  hidden linearVelocity_46 -3.2643264166742904e-09 -1.0957755876006559e-08 1.0657498689982393e-11
  hidden angularVelocity_46 -3.562531413876163e-08 1.73048162526157e-08 -2.2883739836736074e-07
  translation -0.3711687244468617 -8.870613412545643e-05 -0.5986314658497971
  rotation -0.5184280848148248 0.6045625591851804 0.6047614677760961 2.1825719652241644
  controller "mapping"
  supervisor TRUE
  camera_width 50
  camera_height 50
  turretSlot [
    InertialUnit {
      rotation 0 1 0 3.14
    }
    DEF righthinge HingeJoint {
      jointParameters HingeJointParameters {
        position -7.874956133148489e-05
        axis -1 0 0
        anchor 0 0.025 0
      }
      device [
        RotationalMotor {
          name "right wheel motor"
          consumptionFactor 70
          controlPID 8 2 0.5
        }
        PositionSensor {
          name "right wheel sensor"
        }
      ]
      endPoint Solid {
        translation 0.045009957783799924 0.025013382701745798 -2.4670876046677298e-05
        rotation 0.9999993203003528 0.0010053333805666793 -0.000590511326163827 4.636915871562513
        children [
          DEF WHEEL Transform {
            translation -0.007 0.01 -0.05
            rotation 0 0 1 1.57
            children [
              Shape {
                appearance PBRAppearance {
                  baseColor 0 0 0
                  transparency 1
                  roughness 1
                  metalness 0
                }
                geometry Cylinder {
                  height 0.01
                  radius 0.02
                }
              }
            ]
            rotationStep 0.25
          }
        ]
        name "right wheel(1)"
        boundingObject USE WHEEL
        physics DEF PHYSICS_WHEEL Physics {
          density -1
          mass 0.05
        }
        rotationStep 0.25
      }
    }
    DEF lefthinge HingeJoint {
      jointParameters HingeJointParameters {
        position -7.356310794821649e-05
        axis -1 0 0
        anchor 0 0.025 0
      }
      device [
        RotationalMotor {
          name "left wheel motor"
          consumptionFactor 70
          controlPID 8 0 0
        }
        PositionSensor {
          name "left wheel sensor"
        }
      ]
      endPoint Solid {
        translation -0.04501012942703764 0.024977675341672907 -4.5735618557034e-05
        rotation -0.9999982111556941 0.000472844341005739 -0.0018314212079936264 1.242507457312557
        children [
          DEF WHEEL Transform {
            translation 0.007 0 -0.05
            rotation 0 0 1 1.57
            children [
              Shape {
                appearance PBRAppearance {
                  baseColor 0.1 0.1 0.1
                  transparency 1
                  roughness 1
                  metalness 0
                }
                geometry Cylinder {
                  height 0.01
                  radius 0.02
                }
              }
            ]
            rotationStep 0.25
          }
        ]
        name "left wheel(1)"
        boundingObject USE WHEEL
        physics DEF PHYSICS_WHEEL Physics {
          density -1
          mass 0.05
        }
      }
    }
    DEF front_ds DistanceSensor {
      translation 0 0 -0.045
      rotation 0 1 0 1.5708
      name "front_ds"
      recognitionColors [
        0 0 0
      ]
      lookupTable [
        0 0 0
        1.27 1.27 0
      ]
    }
    DEF right_ds DistanceSensor {
      translation 0.035 -0.01 -0.01
      name "right_ds"
      lookupTable [
        0 0 0
        1.27 1.27 0
      ]
    }
    DEF left_ds DistanceSensor {
      translation -0.035 -0.01 -0.01
      rotation 0 1 0 3.14159
      name "left_ds"
      lookupTable [
        0 0 0
        1.27 1.27 0
      ]
    }
    Camera {
      translation 0 0 0.021
      rotation 0 1 0 1.57
      name "camera1"
      recognitionColors [
        1 1 0
      ]
      fieldOfView 3.14
      width 256
      height 256
      projection "spherical"
      recognition Recognition {
      }
    }
  ]
}
WoodenBox {
  translation -0.10697600000853617 0.04980383030004467 -0.28006997900517033
  rotation 4.929275494421577e-09 1 -3.58932935644659e-10 7.244751898494679e-08
  size 0.1 0.1 0.2
  mass 0.5
}
